<?xml version="1.0"?>
<robot xmlns:xacro="http://www.ros.org/wiki/xacro">



    <material name="white">
        <color rgba="1 1 1 1" />
    </material>

    <material name="orange">
        <color rgba="1 0.3 0.1 1"/>
    </material>

    <material name="blue">
        <color rgba="0.2 0.2 1 1"/>
    </material>

    <material name="black">
        <color rgba="0 0 0 1"/>
    </material>

    <material name="red">
        <color rgba="1 0 0 1"/>
    </material>

    <!-- BASE LINK -->

    <link name="base_link">

    </link>

    <!-- BASE_FOOTPRINT LINK -->

    <!-- <joint name="base_footprint_joint" type="fixed">
        <parent link="base_link"/>
        <child link="base_footprint"/>
        <origin xyz="0 0 0" rpy="0 0 0"/>
    </joint>

    <link name="base_footprint">
    </link> -->

    <!-- CHASSIS LINK -->

    <joint name="chassis_joint" type="fixed">
        <parent link="base_link"/>
        <child link="chassis"/>
        <origin xyz="0 0 0" rpy="0 0 0"/>
    </joint>

<link
    name="chassis">
    <inertial>
      <origin
        xyz="0.18547 0.0028349 0.071598"
        rpy="0 0 0" />
      <mass
        value="10.378" />
      <inertia
        ixx="0.15"
        ixy="0.0023"
        ixz="0.0284"
        iyy="0.3813"
        iyz="0.0012"
        izz="0.4504" />
    </inertial>
    <visual>
      <origin
        xyz="0 0 0"
        rpy="0 0 0" />
      <geometry>
        <mesh
          filename="file://$(find mecapkg)/meshes/chassis.stl" />
      </geometry>
      <material
        name="">
        <color
          rgba="0.79216 0.81961 0.93333 1" />
      </material>
    </visual>
    <collision>
      <origin
        xyz="0 0 0"
        rpy="0 0 0" />
      <geometry>
        <mesh
          filename="file://$(find mecapkg)/meshes/chassis.stl" />
      </geometry>
    </collision>
  </link>
  <link
    name="fl">
    <inertial>
      <origin
        xyz="0 0.076094 0"
        rpy="0 0 0" />
      <mass
        value="6" />
      <inertia
        ixx="0.0165"
        ixy="0"
        ixz="0"
        iyy="0.026"
        iyz="0"
        izz="0.0165" />
    </inertial>
    <visual>
      <origin
        xyz="0 0 0"
        rpy="0 0 0" />
      <geometry>
        <mesh
          filename="file://$(find mecapkg)/meshes/fl.stl" />
      </geometry>
      <material
        name="">
        <color
          rgba="0.79216 0.81961 0.93333 1" />
      </material>
    </visual>
    <collision>
      <origin
        xyz="0 0 0"
        rpy="0 0 0" />
      <geometry>
        <mesh
          filename="file://$(find mecapkg)/meshes/fl.stl" />
      </geometry>
    </collision>
  </link>
  <joint
    name="flj"
    type="continuous">
    <origin
      xyz="0.25813 0.18198 -0.0085"
      rpy="0 0 0" />
    <parent
      link="chassis" />
    <child
      link="fl" />
    <axis
      xyz="0 1 0" />
  </joint>
  <link
    name="br">
    <inertial>
      <origin
        xyz="0 -0.076094 0"
        rpy="0 0 0" />
      <mass
        value="6" />
      <inertia
        ixx="0.0165"
        ixy="0"
        ixz="0"
        iyy="0.026"
        iyz="0"
        izz="0.0165" />
    </inertial>
    <visual>
      <origin
        xyz="0 0 0"
        rpy="0 0 0" />
      <geometry>
        <mesh
          filename="file://$(find mecapkg)/meshes/br.stl" />
      </geometry>
      <material
        name="">
        <color
          rgba="0.79216 0.81961 0.93333 1" />
      </material>
    </visual>
    <collision>
      <origin
        xyz="0 0 0"
        rpy="0 0 0" />
      <geometry>
        <mesh
          filename="file://$(find mecapkg)/meshes/br.stl" />
      </geometry>
    </collision>
  </link>
  <joint
    name="brj"
    type="continuous">
    <origin
      xyz="-0.377 -0.18199 -0.0085"
      rpy="0 0 0" />
    <parent
      link="chassis" />
    <child
      link="br" />
    <axis
      xyz="0 1 0" />
  </joint>
  <link
    name="fr">
    <inertial>
      <origin
        xyz="0 -0.077001 0"
        rpy="0 0 0" />
      <mass
        value="6" />
      <inertia
        ixx="0.0156"
        ixy="0"
        ixz="0"
        iyy="0.0244"
        iyz="0"
        izz="0.0156" />
    </inertial>
    <visual>
      <origin
        xyz="0 0 0"
        rpy="0 0 0" />
      <geometry>
        <mesh
          filename="file://$(find mecapkg)/meshes/fr.stl" />
      </geometry>
      <material
        name="">
        <color
          rgba="0.79216 0.81961 0.93333 1" />
      </material>
    </visual>
    <collision>
      <origin
        xyz="0 0 0"
        rpy="0 0 0" />
      <geometry>
        <mesh
          filename="file://$(find mecapkg)/meshes/fr.stl" />
      </geometry>
    </collision>
  </link>
  <joint
    name="frj"
    type="continuous">
    <origin
      xyz="0.25813 -0.18199 -0.0085"
      rpy="0 0 0" />
    <parent
      link="chassis" />
    <child
      link="fr" />
    <axis
      xyz="0 1 0" />
  </joint>
  <link
    name="bl">
    <inertial>
      <origin
        xyz="0 0.077001 0"
        rpy="0 0 0" />
      <mass
        value="6" />
      <inertia
        ixx="0.0156"
        ixy="0"
        ixz="0"
        iyy="0.0244"
        iyz="0"
        izz="0.0156" />
    </inertial>
    <visual>
      <origin
        xyz="0 0 0"
        rpy="0 0 0" />
      <geometry>
        <mesh
          filename="file://$(find mecapkg)/meshes/bl.stl" />
      </geometry>
      <material
        name="">
        <color
          rgba="0.79216 0.81961 0.93333 1" />
      </material>
    </visual>
    <collision>
      <origin
        xyz="0 0 0"
        rpy="0 0 0" />
      <geometry>
        <mesh
          filename="file://$(find mecapkg)/meshes/bl.stl" />
      </geometry>
    </collision>
  </link>
  <joint
    name="blj"
    type="continuous">
    <origin
      xyz="-0.377 0.18198 -0.0085"
      rpy="0 0 0" />
    <parent
      link="chassis" />
    <child
      link="bl" />
    <axis
      xyz="0 1 0" />
  </joint>
</robot>